Workbook

Sheet 项目特征
A1: 规模计数时机 | C1: 估算早期 | D1: =IF(项目特征!C1='模板使用说明&基础参数'!H50,'模板使用说明&基础参数'!I50,IF(项目特征!C1='模板使用说明&基础参数'!H51,'模板使用说明&基础参数'!I51,IF(项目特征!C1='模板使用说明&基础参数'!H52,'模板使用说明&基础参数'!I52,IF(项目特征!C1='模板使用说明&基础参数'!H53,'模板使用说明&基础参数'!I53,1)))) | F1: 开发平台为（低代码开发）需填写此表格下拉选项 | G1: 下拉选项
A2: 应用类型 | C2: 业务处理 | D2: =VLOOKUP($C$2,'模板使用说明&基础参数'!$G$9:$I$16,3,FALSE) | F2: 智能助手开发
A3: 非功能性 特征 | B3: 分布式处理 | C3: 通过网络进行客户端/服务器及网络基础计算机系统分布处理和传输 | D3: =IF(C3='模板使用说明&基础参数'!H19,'模板使用说明&基础参数'!I19,IF(C3='模板使用说明&基础参数'!H20,'模板使用说明&基础参数'!I20,IF(C3='模板使用说明&基础参数'!H21,'模板使用说明&基础参数'!I21,0))) | F3: 数据工厂开发
B4: 性能 | C4: 为满足性能需求事项，要求设计阶段进行性能分析，或在设计、开发阶段使用分析工具 | D4: =IF(C4='模板使用说明&基础参数'!H22,'模板使用说明&基础参数'!I22,IF(C4='模板使用说明&基础参数'!H23,'模板使用说明&基础参数'!I23,IF(C4='模板使用说明&基础参数'!H24,'模板使用说明&基础参数'!I24,0))) | F4: 聚合表
B5: 可靠性 | C5: 发生故障时可轻易修复，带来一定不便或经济损失 | D5: =IF(C5='模板使用说明&基础参数'!H25,'模板使用说明&基础参数'!I25,IF(C5='模板使用说明&基础参数'!H26,'模板使用说明&基础参数'!I26,IF(C5='模板使用说明&基础参数'!H27,'模板使用说明&基础参数'!I27,0))) | F5: 自定义前端组件/插件开发
B6: 多重站点 | C6: 在用途类似的硬件或软件环境下运行 | D6: =IF(C6='模板使用说明&基础参数'!H28,'模板使用说明&基础参数'!I28,IF(C6='模板使用说明&基础参数'!H29,'模板使用说明&基础参数'!I29,IF(C6='模板使用说明&基础参数'!H30,'模板使用说明&基础参数'!I30,0))) | F6: 与外部系统对接且需封装中间件
A7: 完整性级别 | C7: 完整性级别为A同时为达成完整性级别要求在软件开发全生命周期均采取了特定、明确的措施 | D7: =IF(C7='模板使用说明&基础参数'!H45,'模板使用说明&基础参数'!I45,IF(C7='模板使用说明&基础参数'!H46,'模板使用说明&基础参数'!I46,IF(C7='模板使用说明&基础参数'!H47,'模板使用说明&基础参数'!I47,1))) | F7: 原始数据无法直接使用需编写SQL
A8: 开发语言 | C8: JAVA、C++、C#及其他同级别语言/平台 | D8: =IF(C8='模板使用说明&基础参数'!H34,'模板使用说明&基础参数'!I34,IF(C8='模板使用说明&基础参数'!H35,'模板使用说明&基础参数'!I35,IF(C8='模板使用说明&基础参数'!H36,'模板使用说明&基础参数'!I36,1)))
A9: 开发团队背景 | C9: 为本行业开发过类似的项目 | D9: =IF(C9='模板使用说明&基础参数'!H40,'模板使用说明&基础参数'!I40,IF(C9='模板使用说明&基础参数'!H41,'模板使用说明&基础参数'!I41,IF(C9='模板使用说明&基础参数'!H42,'模板使用说明&基础参数'!I42,1)))
A10: 开发平台 | C10: 常规开发 | D10: {=IF(C10='模板使用说明&基础参数'!H56,'模板使用说明&基础参数'!I56,IF(C10='模板使用说明&基础参数'!H57,'模板使用说明&基础参数'!I57,1))+IF(C10='模板使用说明&基础参数'!H57,SUM(IF(G2:G7="是",0.05,0)),0)}

Sheet 规模估算
A1: 规模估算方法 | C1: 估算功能点 | D1: 请选择规模估算方法，缺省为“估算功能点”
A2: 功能点合计 | C2: =J18 | D2: 单位：FP
A3: 调整后功能点 | C3: =M18 | D3: 单位：FP
A5: 编号 | B5: 子系统 | C5: 一级模块 | D5: 二级模块 | E5: 三级模块 | F5: 四级模块 | G5: 功能项描述 | H5: 功能点计数项名称 | I5: 类别 | J5: UFP | K5: 重用程度 | L5: 修改类型 | M5: US | N5: 备注
A6: =ROW()-5 | B6: 客户管理系统 | C6: 客户准入 | D6: 资料采集 | E6: 客户信息 | G6: 新增客户基础资料录入与校验 | H6: 客户基础资料维护 | I6: ILF | J6: =IF(I6="ILF",IF($C$1="预估功能点",'模板使用说明&基础参数'!$E$15,'模板使用说明&基础参数'!$E$22),IF(I6="EIF",IF($C$1="预估功能点",'模板使用说明&基础参数'!$E$16,'模板使用说明&基础参数'!$E$23),IF(I6="EI",IF($C$1="预估功能点",'模板使用说明&基础参数'!$E$17,'模板使用说明&基础参数'!$E$24),IF(I6="EO",IF($C$1="预估功能点",'模板使用说明&基础参数'!$E$18,'模板使用说明&基础参数'!$E$25),IF(I6="EQ",IF($C$1="预估功能点",'模板使用说明&基础参数'!$E$19,'模板使用说明&基础参数'!$E$26),""))))) | K6: 低 | L6: 新增 | M6: =IF(J6="","",IF(K6="高",IF(L6="删除",J6*'模板使用说明&基础参数'!$E$5*'模板使用说明&基础参数'!$E$12,IF(L6="修改",J6*'模板使用说明&基础参数'!$E$5*'模板使用说明&基础参数'!$E$11,J6*'模板使用说明&基础参数'!$E$5*'模板使用说明&基础参数'!$E$10)),IF(K6="中",IF(L6="删除",J6*'模板使用说明&基础参数'!$E$6*'模板使用说明&基础参数'!$E$12,IF(L6="修改",J6*'模板使用说明&基础参数'!$E$6*'模板使用说明&基础参数'!$E$11,J6*'模板使用说明&基础参数'!$E$6*'模板使用说明&基础参数'!$E$10)),IF(L6="删除",J6*'模板使用说明&基础参数'!$E$7*'模板使用说明&基础参数'!$E$12,IF(L6="修改",J6*'模板使用说明&基础参数'!$E$7*'模板使用说明&基础参数'!$E$11,J6*'模板使用说明&基础参数'!$E$7*'模板使用说明&基础参数'!$E$10))))) | N6: 类别原因：ILF，新增客户基础资料录入与校验（客户基础资料维护），原始说明：新增客户主数据组，用于维护系统内部持久业务数据或状态记录，属于内部逻辑文件；复用原因：低，本次能力相对独立，需要新增主要业务流程、数据结构或处理逻辑；修改类型原因：新增，本次新增 客户基础资料维护 相关能力。
A7: =ROW()-5 | B7: 客户管理系统 | C7: 客户准入 | D7: 资料采集 | E7: 影像附件 | G7: 维护客户证件和资质附件清单 | H7: 客户附件资料维护 | I7: ILF | J7: =IF(I7="ILF",IF($C$1="预估功能点",'模板使用说明&基础参数'!$E$15,'模板使用说明&基础参数'!$E$22),IF(I7="EIF",IF($C$1="预估功能点",'模板使用说明&基础参数'!$E$16,'模板使用说明&基础参数'!$E$23),IF(I7="EI",IF($C$1="预估功能点",'模板使用说明&基础参数'!$E$17,'模板使用说明&基础参数'!$E$24),IF(I7="EO",IF($C$1="预估功能点",'模板使用说明&基础参数'!$E$18,'模板使用说明&基础参数'!$E$25),IF(I7="EQ",IF($C$1="预估功能点",'模板使用说明&基础参数'!$E$19,'模板使用说明&基础参数'!$E$26),""))))) | K7: 低 | L7: 新增 | M7: =IF(J7="","",IF(K7="高",IF(L7="删除",J7*'模板使用说明&基础参数'!$E$5*'模板使用说明&基础参数'!$E$12,IF(L7="修改",J7*'模板使用说明&基础参数'!$E$5*'模板使用说明&基础参数'!$E$11,J7*'模板使用说明&基础参数'!$E$5*'模板使用说明&基础参数'!$E$10)),IF(K7="中",IF(L7="删除",J7*'模板使用说明&基础参数'!$E$6*'模板使用说明&基础参数'!$E$12,IF(L7="修改",J7*'模板使用说明&基础参数'!$E$6*'模板使用说明&基础参数'!$E$11,J7*'模板使用说明&基础参数'!$E$6*'模板使用说明&基础参数'!$E$10)),IF(L7="删除",J7*'模板使用说明&基础参数'!$E$7*'模板使用说明&基础参数'!$E$12,IF(L7="修改",J7*'模板使用说明&基础参数'!$E$7*'模板使用说明&基础参数'!$E$11,J7*'模板使用说明&基础参数'!$E$7*'模板使用说明&基础参数'!$E$10))))) | N7: 类别原因：ILF，维护客户证件和资质附件清单（客户附件资料维护），原始说明：新增附件清单数据组，用于维护系统内部持久业务数据或状态记录，属于内部逻辑文件；复用原因：低，本次能力相对独立，需要新增主要业务流程、数据结构或处理逻辑；修改类型原因：新增，本次新增 客户附件资料维护 相关能力。
A8: =ROW()-5 | B8: 客户管理系统 | C8: 客户准入 | D8: 外部核验 | E8: 工商信息 | G8: 调用工商信息服务获取客户注册状态 | H8: 工商信息查询接口 | I8: EIF | J8: =IF(I8="ILF",IF($C$1="预估功能点",'模板使用说明&基础参数'!$E$15,'模板使用说明&基础参数'!$E$22),IF(I8="EIF",IF($C$1="预估功能点",'模板使用说明&基础参数'!$E$16,'模板使用说明&基础参数'!$E$23),IF(I8="EI",IF($C$1="预估功能点",'模板使用说明&基础参数'!$E$17,'模板使用说明&基础参数'!$E$24),IF(I8="EO",IF($C$1="预估功能点",'模板使用说明&基础参数'!$E$18,'模板使用说明&基础参数'!$E$25),IF(I8="EQ",IF($C$1="预估功能点",'模板使用说明&基础参数'!$E$19,'模板使用说明&基础参数'!$E$26),""))))) | K8: 中 | L8: 新增 | M8: =IF(J8="","",IF(K8="高",IF(L8="删除",J8*'模板使用说明&基础参数'!$E$5*'模板使用说明&基础参数'!$E$12,IF(L8="修改",J8*'模板使用说明&基础参数'!$E$5*'模板使用说明&基础参数'!$E$11,J8*'模板使用说明&基础参数'!$E$5*'模板使用说明&基础参数'!$E$10)),IF(K8="中",IF(L8="删除",J8*'模板使用说明&基础参数'!$E$6*'模板使用说明&基础参数'!$E$12,IF(L8="修改",J8*'模板使用说明&基础参数'!$E$6*'模板使用说明&基础参数'!$E$11,J8*'模板使用说明&基础参数'!$E$6*'模板使用说明&基础参数'!$E$10)),IF(L8="删除",J8*'模板使用说明&基础参数'!$E$7*'模板使用说明&基础参数'!$E$12,IF(L8="修改",J8*'模板使用说明&基础参数'!$E$7*'模板使用说明&基础参数'!$E$11,J8*'模板使用说明&基础参数'!$E$7*'模板使用说明&基础参数'!$E$10))))) | N8: 类别原因：EIF，调用工商信息服务获取客户注册状态（工商信息查询接口），原始说明：外部参考数据，依赖外部系统维护的数据或接口资料作为参考，属于外部接口文件；复用原因：中，可复用部分既有能力，但需要新增或调整字段、规则、关联关系或处理逻辑；修改类型原因：新增，本次新增 工商信息查询接口 相关能力。
A9: =ROW()-5 | B9: 客户管理系统 | C9: 客户准入 | D9: 资料提交 | E9: 准入申请 | G9: 提交准入申请并写入待审核状态 | H9: 准入申请提交 | I9: EI | J9: =IF(I9="ILF",IF($C$1="预估功能点",'模板使用说明&基础参数'!$E$15,'模板使用说明&基础参数'!$E$22),IF(I9="EIF",IF($C$1="预估功能点",'模板使用说明&基础参数'!$E$16,'模板使用说明&基础参数'!$E$23),IF(I9="EI",IF($C$1="预估功能点",'模板使用说明&基础参数'!$E$17,'模板使用说明&基础参数'!$E$24),IF(I9="EO",IF($C$1="预估功能点",'模板使用说明&基础参数'!$E$18,'模板使用说明&基础参数'!$E$25),IF(I9="EQ",IF($C$1="预估功能点",'模板使用说明&基础参数'!$E$19,'模板使用说明&基础参数'!$E$26),""))))) | K9: 低 | L9: 新增 | M9: =IF(J9="","",IF(K9="高",IF(L9="删除",J9*'模板使用说明&基础参数'!$E$5*'模板使用说明&基础参数'!$E$12,IF(L9="修改",J9*'模板使用说明&基础参数'!$E$5*'模板使用说明&基础参数'!$E$11,J9*'模板使用说明&基础参数'!$E$5*'模板使用说明&基础参数'!$E$10)),IF(K9="中",IF(L9="删除",J9*'模板使用说明&基础参数'!$E$6*'模板使用说明&基础参数'!$E$12,IF(L9="修改",J9*'模板使用说明&基础参数'!$E$6*'模板使用说明&基础参数'!$E$11,J9*'模板使用说明&基础参数'!$E$6*'模板使用说明&基础参数'!$E$10)),IF(L9="删除",J9*'模板使用说明&基础参数'!$E$7*'模板使用说明&基础参数'!$E$12,IF(L9="修改",J9*'模板使用说明&基础参数'!$E$7*'模板使用说明&基础参数'!$E$11,J9*'模板使用说明&基础参数'!$E$7*'模板使用说明&基础参数'!$E$10))))) | N9: 类别原因：EI，提交准入申请并写入待审核状态（准入申请提交），原始说明：外部输入，由用户或外部系统输入并触发业务数据维护或状态变更，属于外部输入；复用原因：低，本次能力相对独立，需要新增主要业务流程、数据结构或处理逻辑；修改类型原因：新增，本次新增 准入申请提交 相关能力。
A10: =ROW()-5 | B10: 客户管理系统 | C10: 客户准入 | D10: 资料提交 | E10: 附件上传 | G10: 上传并关联客户准入附件 | H10: 准入附件上传 | I10: EI | J10: =IF(I10="ILF",IF($C$1="预估功能点",'模板使用说明&基础参数'!$E$15,'模板使用说明&基础参数'!$E$22),IF(I10="EIF",IF($C$1="预估功能点",'模板使用说明&基础参数'!$E$16,'模板使用说明&基础参数'!$E$23),IF(I10="EI",IF($C$1="预估功能点",'模板使用说明&基础参数'!$E$17,'模板使用说明&基础参数'!$E$24),IF(I10="EO",IF($C$1="预估功能点",'模板使用说明&基础参数'!$E$18,'模板使用说明&基础参数'!$E$25),IF(I10="EQ",IF($C$1="预估功能点",'模板使用说明&基础参数'!$E$19,'模板使用说明&基础参数'!$E$26),""))))) | K10: 中 | L10: 新增 | M10: =IF(J10="","",IF(K10="高",IF(L10="删除",J10*'模板使用说明&基础参数'!$E$5*'模板使用说明&基础参数'!$E$12,IF(L10="修改",J10*'模板使用说明&基础参数'!$E$5*'模板使用说明&基础参数'!$E$11,J10*'模板使用说明&基础参数'!$E$5*'模板使用说明&基础参数'!$E$10)),IF(K10="中",IF(L10="删除",J10*'模板使用说明&基础参数'!$E$6*'模板使用说明&基础参数'!$E$12,IF(L10="修改",J10*'模板使用说明&基础参数'!$E$6*'模板使用说明&基础参数'!$E$11,J10*'模板使用说明&基础参数'!$E$6*'模板使用说明&基础参数'!$E$10)),IF(L10="删除",J10*'模板使用说明&基础参数'!$E$7*'模板使用说明&基础参数'!$E$12,IF(L10="修改",J10*'模板使用说明&基础参数'!$E$7*'模板使用说明&基础参数'!$E$11,J10*'模板使用说明&基础参数'!$E$7*'模板使用说明&基础参数'!$E$10))))) | N10: 类别原因：EI，上传并关联客户准入附件（准入附件上传），原始说明：外部输入，由用户或外部系统输入并触发业务数据维护或状态变更，属于外部输入；复用原因：中，可复用部分既有能力，但需要新增或调整字段、规则、关联关系或处理逻辑；修改类型原因：新增，本次新增 准入附件上传 相关能力。
A11: =ROW()-5 | B11: 客户管理系统 | C11: 客户准入 | D11: 规则校验 | E11: 准入规则 | G11: 按黑名单、资质和区域规则执行准入校验 | H11: 准入规则校验 | I11: EO | J11: =IF(I11="ILF",IF($C$1="预估功能点",'模板使用说明&基础参数'!$E$15,'模板使用说明&基础参数'!$E$22),IF(I11="EIF",IF($C$1="预估功能点",'模板使用说明&基础参数'!$E$16,'模板使用说明&基础参数'!$E$23),IF(I11="EI",IF($C$1="预估功能点",'模板使用说明&基础参数'!$E$17,'模板使用说明&基础参数'!$E$24),IF(I11="EO",IF($C$1="预估功能点",'模板使用说明&基础参数'!$E$18,'模板使用说明&基础参数'!$E$25),IF(I11="EQ",IF($C$1="预估功能点",'模板使用说明&基础参数'!$E$19,'模板使用说明&基础参数'!$E$26),""))))) | K11: 低 | L11: 新增 | M11: =IF(J11="","",IF(K11="高",IF(L11="删除",J11*'模板使用说明&基础参数'!$E$5*'模板使用说明&基础参数'!$E$12,IF(L11="修改",J11*'模板使用说明&基础参数'!$E$5*'模板使用说明&基础参数'!$E$11,J11*'模板使用说明&基础参数'!$E$5*'模板使用说明&基础参数'!$E$10)),IF(K11="中",IF(L11="删除",J11*'模板使用说明&基础参数'!$E$6*'模板使用说明&基础参数'!$E$12,IF(L11="修改",J11*'模板使用说明&基础参数'!$E$6*'模板使用说明&基础参数'!$E$11,J11*'模板使用说明&基础参数'!$E$6*'模板使用说明&基础参数'!$E$10)),IF(L11="删除",J11*'模板使用说明&基础参数'!$E$7*'模板使用说明&基础参数'!$E$12,IF(L11="修改",J11*'模板使用说明&基础参数'!$E$7*'模板使用说明&基础参数'!$E$11,J11*'模板使用说明&基础参数'!$E$7*'模板使用说明&基础参数'!$E$10))))) | N11: 类别原因：EO，按黑名单、资质和区域规则执行准入校验（准入规则校验），原始说明：派生输出，包含派生处理、通知、导出、统计或风险提示等输出，属于外部输出；复用原因：低，本次能力相对独立，需要新增主要业务流程、数据结构或处理逻辑；修改类型原因：新增，本次新增 准入规则校验 相关能力。
A12: =ROW()-5 | B12: 客户管理系统 | C12: 客户准入 | D12: 风险提示 | E12: 提示生成 | G12: 生成准入风险提示和处理建议 | H12: 准入风险提示 | I12: EO | J12: =IF(I12="ILF",IF($C$1="预估功能点",'模板使用说明&基础参数'!$E$15,'模板使用说明&基础参数'!$E$22),IF(I12="EIF",IF($C$1="预估功能点",'模板使用说明&基础参数'!$E$16,'模板使用说明&基础参数'!$E$23),IF(I12="EI",IF($C$1="预估功能点",'模板使用说明&基础参数'!$E$17,'模板使用说明&基础参数'!$E$24),IF(I12="EO",IF($C$1="预估功能点",'模板使用说明&基础参数'!$E$18,'模板使用说明&基础参数'!$E$25),IF(I12="EQ",IF($C$1="预估功能点",'模板使用说明&基础参数'!$E$19,'模板使用说明&基础参数'!$E$26),""))))) | K12: 低 | L12: 新增 | M12: =IF(J12="","",IF(K12="高",IF(L12="删除",J12*'模板使用说明&基础参数'!$E$5*'模板使用说明&基础参数'!$E$12,IF(L12="修改",J12*'模板使用说明&基础参数'!$E$5*'模板使用说明&基础参数'!$E$11,J12*'模板使用说明&基础参数'!$E$5*'模板使用说明&基础参数'!$E$10)),IF(K12="中",IF(L12="删除",J12*'模板使用说明&基础参数'!$E$6*'模板使用说明&基础参数'!$E$12,IF(L12="修改",J12*'模板使用说明&基础参数'!$E$6*'模板使用说明&基础参数'!$E$11,J12*'模板使用说明&基础参数'!$E$6*'模板使用说明&基础参数'!$E$10)),IF(L12="删除",J12*'模板使用说明&基础参数'!$E$7*'模板使用说明&基础参数'!$E$12,IF(L12="修改",J12*'模板使用说明&基础参数'!$E$7*'模板使用说明&基础参数'!$E$11,J12*'模板使用说明&基础参数'!$E$7*'模板使用说明&基础参数'!$E$10))))) | N12: 类别原因：EO，生成准入风险提示和处理建议（准入风险提示），原始说明：派生输出，包含派生处理、通知、导出、统计或风险提示等输出，属于外部输出；复用原因：低，本次能力相对独立，需要新增主要业务流程、数据结构或处理逻辑；修改类型原因：新增，本次新增 准入风险提示 相关能力。
A13: =ROW()-5 | B13: 客户管理系统 | C13: 客户准入 | D13: 审批处理 | E13: 审批结果 | G13: 保存审批结论并更新客户准入状态 | H13: 准入审批结果维护 | I13: EI | J13: =IF(I13="ILF",IF($C$1="预估功能点",'模板使用说明&基础参数'!$E$15,'模板使用说明&基础参数'!$E$22),IF(I13="EIF",IF($C$1="预估功能点",'模板使用说明&基础参数'!$E$16,'模板使用说明&基础参数'!$E$23),IF(I13="EI",IF($C$1="预估功能点",'模板使用说明&基础参数'!$E$17,'模板使用说明&基础参数'!$E$24),IF(I13="EO",IF($C$1="预估功能点",'模板使用说明&基础参数'!$E$18,'模板使用说明&基础参数'!$E$25),IF(I13="EQ",IF($C$1="预估功能点",'模板使用说明&基础参数'!$E$19,'模板使用说明&基础参数'!$E$26),""))))) | K13: 低 | L13: 新增 | M13: =IF(J13="","",IF(K13="高",IF(L13="删除",J13*'模板使用说明&基础参数'!$E$5*'模板使用说明&基础参数'!$E$12,IF(L13="修改",J13*'模板使用说明&基础参数'!$E$5*'模板使用说明&基础参数'!$E$11,J13*'模板使用说明&基础参数'!$E$5*'模板使用说明&基础参数'!$E$10)),IF(K13="中",IF(L13="删除",J13*'模板使用说明&基础参数'!$E$6*'模板使用说明&基础参数'!$E$12,IF(L13="修改",J13*'模板使用说明&基础参数'!$E$6*'模板使用说明&基础参数'!$E$11,J13*'模板使用说明&基础参数'!$E$6*'模板使用说明&基础参数'!$E$10)),IF(L13="删除",J13*'模板使用说明&基础参数'!$E$7*'模板使用说明&基础参数'!$E$12,IF(L13="修改",J13*'模板使用说明&基础参数'!$E$7*'模板使用说明&基础参数'!$E$11,J13*'模板使用说明&基础参数'!$E$7*'模板使用说明&基础参数'!$E$10))))) | N13: 类别原因：EI，保存审批结论并更新客户准入状态（准入审批结果维护），原始说明：外部输入，由用户或外部系统输入并触发业务数据维护或状态变更，属于外部输入；复用原因：低，本次能力相对独立，需要新增主要业务流程、数据结构或处理逻辑；修改类型原因：新增，本次新增 准入审批结果维护 相关能力。
A14: =ROW()-5 | B14: 客户管理系统 | C14: 客户准入 | D14: 查询展示 | E14: 申请列表 | G14: 按条件查询客户准入申请列表 | H14: 准入申请列表查询 | I14: EQ | J14: =IF(I14="ILF",IF($C$1="预估功能点",'模板使用说明&基础参数'!$E$15,'模板使用说明&基础参数'!$E$22),IF(I14="EIF",IF($C$1="预估功能点",'模板使用说明&基础参数'!$E$16,'模板使用说明&基础参数'!$E$23),IF(I14="EI",IF($C$1="预估功能点",'模板使用说明&基础参数'!$E$17,'模板使用说明&基础参数'!$E$24),IF(I14="EO",IF($C$1="预估功能点",'模板使用说明&基础参数'!$E$18,'模板使用说明&基础参数'!$E$25),IF(I14="EQ",IF($C$1="预估功能点",'模板使用说明&基础参数'!$E$19,'模板使用说明&基础参数'!$E$26),""))))) | K14: 中 | L14: 新增 | M14: =IF(J14="","",IF(K14="高",IF(L14="删除",J14*'模板使用说明&基础参数'!$E$5*'模板使用说明&基础参数'!$E$12,IF(L14="修改",J14*'模板使用说明&基础参数'!$E$5*'模板使用说明&基础参数'!$E$11,J14*'模板使用说明&基础参数'!$E$5*'模板使用说明&基础参数'!$E$10)),IF(K14="中",IF(L14="删除",J14*'模板使用说明&基础参数'!$E$6*'模板使用说明&基础参数'!$E$12,IF(L14="修改",J14*'模板使用说明&基础参数'!$E$6*'模板使用说明&基础参数'!$E$11,J14*'模板使用说明&基础参数'!$E$6*'模板使用说明&基础参数'!$E$10)),IF(L14="删除",J14*'模板使用说明&基础参数'!$E$7*'模板使用说明&基础参数'!$E$12,IF(L14="修改",J14*'模板使用说明&基础参数'!$E$7*'模板使用说明&基础参数'!$E$11,J14*'模板使用说明&基础参数'!$E$7*'模板使用说明&基础参数'!$E$10))))) | N14: 类别原因：EQ，按条件查询客户准入申请列表（准入申请列表查询），原始说明：外部查询，按条件读取并展示已有数据，未产生复杂派生处理，属于外部查询；复用原因：中，可复用部分既有能力，但需要新增或调整字段、规则、关联关系或处理逻辑；修改类型原因：新增，本次新增 准入申请列表查询 相关能力。
A15: =ROW()-5 | B15: 客户管理系统 | C15: 客户准入 | D15: 查询展示 | E15: 申请详情 | G15: 展示客户资料、校验结果和审批轨迹 | H15: 准入申请详情查询 | I15: EQ | J15: =IF(I15="ILF",IF($C$1="预估功能点",'模板使用说明&基础参数'!$E$15,'模板使用说明&基础参数'!$E$22),IF(I15="EIF",IF($C$1="预估功能点",'模板使用说明&基础参数'!$E$16,'模板使用说明&基础参数'!$E$23),IF(I15="EI",IF($C$1="预估功能点",'模板使用说明&基础参数'!$E$17,'模板使用说明&基础参数'!$E$24),IF(I15="EO",IF($C$1="预估功能点",'模板使用说明&基础参数'!$E$18,'模板使用说明&基础参数'!$E$25),IF(I15="EQ",IF($C$1="预估功能点",'模板使用说明&基础参数'!$E$19,'模板使用说明&基础参数'!$E$26),""))))) | K15: 中 | L15: 新增 | M15: =IF(J15="","",IF(K15="高",IF(L15="删除",J15*'模板使用说明&基础参数'!$E$5*'模板使用说明&基础参数'!$E$12,IF(L15="修改",J15*'模板使用说明&基础参数'!$E$5*'模板使用说明&基础参数'!$E$11,J15*'模板使用说明&基础参数'!$E$5*'模板使用说明&基础参数'!$E$10)),IF(K15="中",IF(L15="删除",J15*'模板使用说明&基础参数'!$E$6*'模板使用说明&基础参数'!$E$12,IF(L15="修改",J15*'模板使用说明&基础参数'!$E$6*'模板使用说明&基础参数'!$E$11,J15*'模板使用说明&基础参数'!$E$6*'模板使用说明&基础参数'!$E$10)),IF(L15="删除",J15*'模板使用说明&基础参数'!$E$7*'模板使用说明&基础参数'!$E$12,IF(L15="修改",J15*'模板使用说明&基础参数'!$E$7*'模板使用说明&基础参数'!$E$11,J15*'模板使用说明&基础参数'!$E$7*'模板使用说明&基础参数'!$E$10))))) | N15: 类别原因：EQ，展示客户资料、校验结果和审批轨迹（准入申请详情查询），原始说明：外部查询，按条件读取并展示已有数据，未产生复杂派生处理，属于外部查询；复用原因：中，可复用部分既有能力，但需要新增或调整字段、规则、关联关系或处理逻辑；修改类型原因：新增，本次新增 准入申请详情查询 相关能力。
A16: =ROW()-5 | B16: 客户管理系统 | C16: 客户准入 | D16: 通知集成 | E16: 审批通知 | G16: 审批完成后推送站内信和待办消息 | H16: 准入结果通知 | I16: EO | J16: =IF(I16="ILF",IF($C$1="预估功能点",'模板使用说明&基础参数'!$E$15,'模板使用说明&基础参数'!$E$22),IF(I16="EIF",IF($C$1="预估功能点",'模板使用说明&基础参数'!$E$16,'模板使用说明&基础参数'!$E$23),IF(I16="EI",IF($C$1="预估功能点",'模板使用说明&基础参数'!$E$17,'模板使用说明&基础参数'!$E$24),IF(I16="EO",IF($C$1="预估功能点",'模板使用说明&基础参数'!$E$18,'模板使用说明&基础参数'!$E$25),IF(I16="EQ",IF($C$1="预估功能点",'模板使用说明&基础参数'!$E$19,'模板使用说明&基础参数'!$E$26),""))))) | K16: 中 | L16: 新增 | M16: =IF(J16="","",IF(K16="高",IF(L16="删除",J16*'模板使用说明&基础参数'!$E$5*'模板使用说明&基础参数'!$E$12,IF(L16="修改",J16*'模板使用说明&基础参数'!$E$5*'模板使用说明&基础参数'!$E$11,J16*'模板使用说明&基础参数'!$E$5*'模板使用说明&基础参数'!$E$10)),IF(K16="中",IF(L16="删除",J16*'模板使用说明&基础参数'!$E$6*'模板使用说明&基础参数'!$E$12,IF(L16="修改",J16*'模板使用说明&基础参数'!$E$6*'模板使用说明&基础参数'!$E$11,J16*'模板使用说明&基础参数'!$E$6*'模板使用说明&基础参数'!$E$10)),IF(L16="删除",J16*'模板使用说明&基础参数'!$E$7*'模板使用说明&基础参数'!$E$12,IF(L16="修改",J16*'模板使用说明&基础参数'!$E$7*'模板使用说明&基础参数'!$E$11,J16*'模板使用说明&基础参数'!$E$7*'模板使用说明&基础参数'!$E$10))))) | N16: 类别原因：EO，审批完成后推送站内信和待办消息（准入结果通知），原始说明：派生输出，包含派生处理、通知、导出、统计或风险提示等输出，属于外部输出；复用原因：中，可复用部分既有能力，但需要新增或调整字段、规则、关联关系或处理逻辑；修改类型原因：新增，本次新增 准入结果通知 相关能力。
A17: =ROW()-5 | B17: 客户管理系统 | C17: 客户准入 | D17: 报表导出 | E17: 准入台账 | G17: 导出客户准入台账和风险统计 | H17: 准入台账导出 | I17: EO | J17: =IF(I17="ILF",IF($C$1="预估功能点",'模板使用说明&基础参数'!$E$15,'模板使用说明&基础参数'!$E$22),IF(I17="EIF",IF($C$1="预估功能点",'模板使用说明&基础参数'!$E$16,'模板使用说明&基础参数'!$E$23),IF(I17="EI",IF($C$1="预估功能点",'模板使用说明&基础参数'!$E$17,'模板使用说明&基础参数'!$E$24),IF(I17="EO",IF($C$1="预估功能点",'模板使用说明&基础参数'!$E$18,'模板使用说明&基础参数'!$E$25),IF(I17="EQ",IF($C$1="预估功能点",'模板使用说明&基础参数'!$E$19,'模板使用说明&基础参数'!$E$26),""))))) | K17: 中 | L17: 新增 | M17: =IF(J17="","",IF(K17="高",IF(L17="删除",J17*'模板使用说明&基础参数'!$E$5*'模板使用说明&基础参数'!$E$12,IF(L17="修改",J17*'模板使用说明&基础参数'!$E$5*'模板使用说明&基础参数'!$E$11,J17*'模板使用说明&基础参数'!$E$5*'模板使用说明&基础参数'!$E$10)),IF(K17="中",IF(L17="删除",J17*'模板使用说明&基础参数'!$E$6*'模板使用说明&基础参数'!$E$12,IF(L17="修改",J17*'模板使用说明&基础参数'!$E$6*'模板使用说明&基础参数'!$E$11,J17*'模板使用说明&基础参数'!$E$6*'模板使用说明&基础参数'!$E$10)),IF(L17="删除",J17*'模板使用说明&基础参数'!$E$7*'模板使用说明&基础参数'!$E$12,IF(L17="修改",J17*'模板使用说明&基础参数'!$E$7*'模板使用说明&基础参数'!$E$11,J17*'模板使用说明&基础参数'!$E$7*'模板使用说明&基础参数'!$E$10))))) | N17: 类别原因：EO，导出客户准入台账和风险统计（准入台账导出），原始说明：派生输出，包含派生处理、通知、导出、统计或风险提示等输出，属于外部输出；复用原因：中，可复用部分既有能力，但需要新增或调整字段、规则、关联关系或处理逻辑；修改类型原因：新增，本次新增 准入台账导出 相关能力。
A18: 合计 | J18: =SUM(J6:J17) | M18: =SUM(M6:M17)

Sheet 开发费用估算
A1: 规模估算结果（单位：功能点） | C1: ='规模估算'!M18 | D1: 未调整功能点
A2: 规模变更调整因子取值 | C2: =项目特征!D1 | D2: =项目特征!C1
A3: 调整后规模（单位：功能点） | C3: =C1*C2 | D3: 调整后功能点
A4: 基准生产率（单位：人时/功能点） | C4: =C5*0.8 | D4: 下限
C5: 7.88 | D5: 中位数
C6: =C5*1.2 | D6: 上限
A7: 未调整工作量（单位：人天） | C7: =C3*C4/8 | D7: 下限
C8: =C3*C5/8 | D8: 中值
C9: =C3*C6/8 | D9: 上限
A10: 调整因子 | B10: 应用类型 | C10: =项目特征!D2 | D10: =IFERROR(项目特征!C2&":"&VLOOKUP(项目特征!C2,'模板使用说明&基础参数'!$G$10:$H$16,2,FALSE),"")
B11: 非功能性特征 | C11: =1+0.025*SUM(项目特征!D3:项目特征!D6) | D11: =IFERROR(B11&"=("&项目特征!B3&项目特征!D3&"+"&项目特征!B4&项目特征!D4&"+"&项目特征!B5&项目特征!D5&"+"&项目特征!B6&项目特征!D6&")*0.025+1","")
B12: 完整性级别 | C12: =项目特征!D7 | D12: =项目特征!C7
B13: 开发语言 | C13: =项目特征!D8 | D13: =项目特征!C8
B14: 开发团队背景 | C14: =项目特征!D9 | D14: =项目特征!C9
B15: 开发平台 | C15: =项目特征!D10 | D15: =项目特征!C10
A16: 调整后工作量（单位：人天） | C16: =C7*C10*C11*C12*C13*C14*C15 | D16: 下限
C17: =C8*C10*C11*C12*C13*C14*C15 | D17: 中值
C18: =C9*C10*C11*C12*C13*C14*C15 | D18: 上限
A19: 人月基准单价（单位：万元/人月） | C19: 2.5 | D19: 人月单价，不包含直接非人力成本
A20: 基准报价（单位：万元） （不包含直接非人力成本） | C20: =C16*C19/21.75 | D20: 下限
C21: =C17*C19/21.75 | D21: 中值
C22: =C18*C19/21.75 | D22: 上限

Sheet 模板使用说明&基础参数
A2: 本模板通常只填写白色区域；
A3: 填写顺序为：填写项目特征->规模估算->查看结果（“开发工作量估算”相关部分）
A4: 深灰 | B4: 模板固定部分，不得修改 | D4: 重用程度调整系数
A5: 浅灰 | B5: 模板固定部分，在必要时统一修改 | D5: 高 | E5: 0.33333333
A6: 绿色 | B6: 自动计算或引用数据，不得修改 | D6: 中 | E6: 0.66666667
A7: 白色 | B7: 需填写或修改内容 | D7: 低 | E7: 1
D9: 修改类型调整系数 | G9: 应用类型 | H9: 描述 | I9: 调整因子
D10: 新增 | E10: 1 | G10: 业务处理 | H10: 办公自动化系统；人事、会计、工资、销售等经营管理及业务处理用软件等 | I10: 1
D11: 修改 | E11: 0.8 | G11: 科技 | H11: 科学计算、模拟、统计分析等 | I11: 1.2
D12: 删除 | E12: 0.2 | G12: 多媒体 | H12: 图形、影像、声音等多媒体应用领域；地理信息系统；教育和娱乐等 | I12: 1.3
G13: 智能信息 | H13: 自然语言处理、人工智能、专家系统等 | I13: 1.5
D14: 预估功能点 | G14: 基础软件/支撑软件 | H14: 操作系统、数据库系统、集成开发环境、自动化开发/设计工具等/设计工具等 | I14: 1.7
D15: ILF | E15: 35 | G15: 通信控制 | H15: 通信协议、仿真、交换机软件、全球定位系统等 | I15: 1.9
D16: EIF | E16: 15 | G16: 流程控制 | H16: 实时控制、机器人控制、嵌入式软件等 | I16: 2
D17: EI
D18: EO | G18: 调整因子 | H18: 判断标准 | I18: 调整因子
D19: EQ | G19: 分布式处理 | H19: 没有明示对分布式处理的需求事项 | I19: -1
H20: 通过网络进行客户端/服务器及网络基础计算机系统分布处理和传输 | I20: 0
D21: 估算功能点 | H21: 在多个服务器及处理器上同时相互执行计算机系统中的处理功能 | I21: 1
D22: ILF | E22: 10 | G22: 性能 | H22: 没有明示对性能的特别需求事项或活动，因此提供基本性能 | I22: -1
D23: EIF | E23: 7 | H23: 应答时间或处理率对高峰时间或所有业务时间都很重要，对连动系统结束处理时间有限制 | I23: 0
D24: EI | E24: 4 | H24: 为满足性能需求事项，要求设计阶段进行性能分析，或在设计、开发阶段使用分析工具 | I24: 1
D25: EO | E25: 5 | G25: 可靠性 | H25: 没有明示对可靠性的特别需求事项或活动，因此提供基本的可靠性 | I25: -1
D26: EQ | E26: 4 | H26: 发生故障时可轻易修复，带来一定不便或经济损失 | I26: 0
H27: 发生故障时很难修复，发生重大经济损失或有生命危害 | I27: 1
D28: 开发平台 | G28: 多重站点 | H28: 在相同用途的硬件或软件环境下运行 | I28: -1
D29: 否 | E29: 0 | H29: 在用途类似的硬件或软件环境下运行 | I29: 0
D30: 是 | E30: 0.05 | H30: 在不同用途的硬件或软件环境下运行 | I30: 1
H33: 开发语言 | I33: 调整因子
H34: C及其他同级别语言/平台 | I34: 1.2
H35: JAVA、C++、C#及其他同级别语言/平台 | I35: 1
H36: PowerBuilder、ASP及其他同级别语言/平台 | I36: 0.8
H39: 开发团队背景 | I39: 调整因子
H40: 为本行业开发过类似的项目 | I40: 0.8
H41: 为其他行业开发过类似的项目，或为本行业开发过不同但相关的项目 | I41: 1
H42: 没有同类项目的背景 | I42: 1.2
H44: 完整性级别 | I44: 调整因子
H45: 没有明确的完整性级别或等级为C/D | I45: 1
H46: 完整性级别为A/B同时为达成完整性级别要求采取了特殊的设计及实现方式 | I46: 1.1
H47: 完整性级别为A同时为达成完整性级别要求在软件开发全生命周期均采取了特定、明确的措施 | I47: 1.3
...
